{"trial_id": "0", "hyperparameters": {"space": [{"class_name": "Int", "config": {"name": "embedding_dim", "default": null, "conditions": [], "min_value": 50, "max_value": 300, "step": 50, "sampling": "linear"}}, {"class_name": "Int", "config": {"name": "lstm_units", "default": null, "conditions": [], "min_value": 64, "max_value": 256, "step": 64, "sampling": "linear"}}], "values": {"embedding_dim": 100, "lstm_units": 256}}, "metrics": {"metrics": {}}, "score": null, "best_step": 0, "status": "FAILED", "message": "Traceback (most recent call last):\n  File \"/Users/danayt/anaconda3/envs/learn-env/lib/python3.9/site-packages/keras_tuner/src/engine/base_tuner.py\", line 273, in _try_run_and_update_trial\n    self._run_and_update_trial(trial, *fit_args, **fit_kwargs)\n  File \"/Users/danayt/anaconda3/envs/learn-env/lib/python3.9/site-packages/keras_tuner/src/engine/base_tuner.py\", line 238, in _run_and_update_trial\n    results = self.run_trial(trial, *fit_args, **fit_kwargs)\n  File \"/Users/danayt/anaconda3/envs/learn-env/lib/python3.9/site-packages/keras_tuner/src/engine/tuner.py\", line 314, in run_trial\n    obj_value = self._build_and_fit_model(trial, *args, **copied_kwargs)\n  File \"/Users/danayt/anaconda3/envs/learn-env/lib/python3.9/site-packages/keras_tuner/src/engine/tuner.py\", line 233, in _build_and_fit_model\n    results = self.hypermodel.fit(hp, model, *args, **kwargs)\n  File \"/Users/danayt/anaconda3/envs/learn-env/lib/python3.9/site-packages/keras_tuner/src/engine/hypermodel.py\", line 149, in fit\n    return model.fit(*args, **kwargs)\n  File \"/Users/danayt/anaconda3/envs/learn-env/lib/python3.9/site-packages/keras/src/utils/traceback_utils.py\", line 70, in error_handler\n    raise e.with_traceback(filtered_tb) from None\n  File \"/Users/danayt/anaconda3/envs/learn-env/lib/python3.9/site-packages/tensorflow/python/eager/execute.py\", line 60, in quick_execute\n    tensors = pywrap_tfe.TFE_Py_Execute(ctx._handle, device_name, op_name,\ntensorflow.python.framework.errors_impl.CancelledError: Graph execution error:\n\nDetected at node ArgMax/_22 defined at (most recent call last):\n<stack traces unavailable>\nRecvAsync is cancelled.\n\t [[{{node ArgMax/_22}}]] [Op:__inference_train_function_23128]\n"}